Workbook

Sheet Dashboard
A1: SignalStack | Ops Pulse — Operational Health Dashboard
A2: Weekly snapshot of field operations. Update the Weekly Log tab each week. Metrics auto-calculate here.
A4: KEY PERFORMANCE INDICATORS — CURRENT WEEK
A5: Jobs Completed | B5: On-Time Rate | C5: Callback Rate | D5: Avg Job Duration | E5: Crew Utilization | F5: Open Work Orders
A6: =LOOKUP(2,1/(A10:A2000<>""),B10:B2000) | B6: =LOOKUP(2,1/(A10:A2000<>""),C10:C2000) | C6: =LOOKUP(2,1/(A10:A2000<>""),D10:D2000) | D6: =LOOKUP(2,1/(A10:A2000<>""),E10:E2000) | E6: =LOOKUP(2,1/(A10:A2000<>""),F10:F2000) | F6: =LOOKUP(2,1/(A10:A2000<>""),G10:G2000)
A8: WEEKLY TREND — FULL HISTORY
A9: Week | B9: Jobs Done | C9: On-Time % | D9: Callback % | E9: Avg Hours | F9: Utilization % | G9: Open WOs | H9: Notes | J9: __week_start
A10: =IF($J10="","",YEAR($J10-WEEKDAY($J10,2)+4)&"-W"&TEXT(WEEKNUM($J10,21),"00")) | B10: =IF($J10="","",SUMIFS('Weekly Log'!$C:$C,'Weekly Log'!$A:$A,">="&$J10,'Weekly Log'!$A:$A,"<"&$J10+7)) | C10: =IF($J10="","",IFERROR(COUNTIFS('Weekly Log'!$G:$G,"Y",'Weekly Log'!$A:$A,">="&$J10,'Weekly Log'!$A:$A,"<"&$J10+7)/COUNTIFS('Weekly Log'!$G:$G,"<>",'Weekly Log'!$A:$A,">="&$J10,'Weekly Log'!$A:$A,"<"&$J10+7),0)) | D10: =IF($J10="","",IFERROR(COUNTIFS('Weekly Log'!$H:$H,"Y",'Weekly Log'!$A:$A,">="&$J10,'Weekly Log'!$A:$A,"<"&$J10+7)/COUNTIFS('Weekly Log'!$H:$H,"<>",'Weekly Log'!$A:$A,">="&$J10,'Weekly Log'!$A:$A,"<"&$J10+7),0)) | E10: =IF($J10="","",IFERROR(AVERAGEIFS('Weekly Log'!$F:$F,'Weekly Log'!$A:$A,">="&$J10,'Weekly Log'!$A:$A,"<"&$J10+7),0)) | F10: =IF($J10="","",IFERROR(SUMIFS('Weekly Log'!$F:$F,'Weekly Log'!$A:$A,">="&$J10,'Weekly Log'!$A:$A,"<"&$J10+7)/SUMIFS('Weekly Log'!$E:$E,'Weekly Log'!$A:$A,">="&$J10,'Weekly Log'!$A:$A,"<"&$J10+7),0)) | G10: =IF($J10="","",IFERROR(LOOKUP(2,1/(('Weekly Log'!$A$5:$A$5000>=$J10)*('Weekly Log'!$A$5:$A$5000<$J10+7)*('Weekly Log'!$M$5:$M$5000<>"")),'Weekly Log'!$M$5:$M$5000),0)) | J10: =IF(COUNT('Weekly Log'!$A$5:$A$5000)=0,"",IF(MIN('Weekly Log'!$A$5:$A$5000)+7*(ROW()-10)>MAX('Weekly Log'!$A$5:$A$5000),"",MIN('Weekly Log'!$A$5:$A$5000)+7*(ROW()-10)))
A11: =IF($J11="","",YEAR($J11-WEEKDAY($J11,2)+4)&"-W"&TEXT(WEEKNUM($J11,21),"00")) | B11: =IF($J11="","",SUMIFS('Weekly Log'!$C:$C,'Weekly Log'!$A:$A,">="&$J11,'Weekly Log'!$A:$A,"<"&$J11+7)) | C11: =IF($J11="","",IFERROR(COUNTIFS('Weekly Log'!$G:$G,"Y",'Weekly Log'!$A:$A,">="&$J11,'Weekly Log'!$A:$A,"<"&$J11+7)/COUNTIFS('Weekly Log'!$G:$G,"<>",'Weekly Log'!$A:$A,">="&$J11,'Weekly Log'!$A:$A,"<"&$J11+7),0)) | D11: =IF($J11="","",IFERROR(COUNTIFS('Weekly Log'!$H:$H,"Y",'Weekly Log'!$A:$A,">="&$J11,'Weekly Log'!$A:$A,"<"&$J11+7)/COUNTIFS('Weekly Log'!$H:$H,"<>",'Weekly Log'!$A:$A,">="&$J11,'Weekly Log'!$A:$A,"<"&$J11+7),0)) | E11: =IF($J11="","",IFERROR(AVERAGEIFS('Weekly Log'!$F:$F,'Weekly Log'!$A:$A,">="&$J11,'Weekly Log'!$A:$A,"<"&$J11+7),0)) | F11: =IF($J11="","",IFERROR(SUMIFS('Weekly Log'!$F:$F,'Weekly Log'!$A:$A,">="&$J11,'Weekly Log'!$A:$A,"<"&$J11+7)/SUMIFS('Weekly Log'!$E:$E,'Weekly Log'!$A:$A,">="&$J11,'Weekly Log'!$A:$A,"<"&$J11+7),0)) | G11: =IF($J11="","",IFERROR(LOOKUP(2,1/(('Weekly Log'!$A$5:$A$5000>=$J11)*('Weekly Log'!$A$5:$A$5000<$J11+7)*('Weekly Log'!$M$5:$M$5000<>"")),'Weekly Log'!$M$5:$M$5000),0)) | J11: =IF(COUNT('Weekly Log'!$A$5:$A$5000)=0,"",IF(MIN('Weekly Log'!$A$5:$A$5000)+7*(ROW()-10)>MAX('Weekly Log'!$A$5:$A$5000),"",MIN('Weekly Log'!$A$5:$A$5000)+7*(ROW()-10)))
A12: =IF($J12="","",YEAR($J12-WEEKDAY($J12,2)+4)&"-W"&TEXT(WEEKNUM($J12,21),"00")) | B12: =IF($J12="","",SUMIFS('Weekly Log'!$C:$C,'Weekly Log'!$A:$A,">="&$J12,'Weekly Log'!$A:$A,"<"&$J12+7)) | C12: =IF($J12="","",IFERROR(COUNTIFS('Weekly Log'!$G:$G,"Y",'Weekly Log'!$A:$A,">="&$J12,'Weekly Log'!$A:$A,"<"&$J12+7)/COUNTIFS('Weekly Log'!$G:$G,"<>",'Weekly Log'!$A:$A,">="&$J12,'Weekly Log'!$A:$A,"<"&$J12+7),0)) | D12: =IF($J12="","",IFERROR(COUNTIFS('Weekly Log'!$H:$H,"Y",'Weekly Log'!$A:$A,">="&$J12,'Weekly Log'!$A:$A,"<"&$J12+7)/COUNTIFS('Weekly Log'!$H:$H,"<>",'Weekly Log'!$A:$A,">="&$J12,'Weekly Log'!$A:$A,"<"&$J12+7),0)) | E12: =IF($J12="","",IFERROR(AVERAGEIFS('Weekly Log'!$F:$F,'Weekly Log'!$A:$A,">="&$J12,'Weekly Log'!$A:$A,"<"&$J12+7),0)) | F12: =IF($J12="","",IFERROR(SUMIFS('Weekly Log'!$F:$F,'Weekly Log'!$A:$A,">="&$J12,'Weekly Log'!$A:$A,"<"&$J12+7)/SUMIFS('Weekly Log'!$E:$E,'Weekly Log'!$A:$A,">="&$J12,'Weekly Log'!$A:$A,"<"&$J12+7),0)) | G12: =IF($J12="","",IFERROR(LOOKUP(2,1/(('Weekly Log'!$A$5:$A$5000>=$J12)*('Weekly Log'!$A$5:$A$5000<$J12+7)*('Weekly Log'!$M$5:$M$5000<>"")),'Weekly Log'!$M$5:$M$5000),0)) | H12: Holiday staffing | J12: =IF(COUNT('Weekly Log'!$A$5:$A$5000)=0,"",IF(MIN('Weekly Log'!$A$5:$A$5000)+7*(ROW()-10)>MAX('Weekly Log'!$A$5:$A$5000),"",MIN('Weekly Log'!$A$5:$A$5000)+7*(ROW()-10)))
A13: =IF($J13="","",YEAR($J13-WEEKDAY($J13,2)+4)&"-W"&TEXT(WEEKNUM($J13,21),"00")) | B13: =IF($J13="","",SUMIFS('Weekly Log'!$C:$C,'Weekly Log'!$A:$A,">="&$J13,'Weekly Log'!$A:$A,"<"&$J13+7)) | C13: =IF($J13="","",IFERROR(COUNTIFS('Weekly Log'!$G:$G,"Y",'Weekly Log'!$A:$A,">="&$J13,'Weekly Log'!$A:$A,"<"&$J13+7)/COUNTIFS('Weekly Log'!$G:$G,"<>",'Weekly Log'!$A:$A,">="&$J13,'Weekly Log'!$A:$A,"<"&$J13+7),0)) | D13: =IF($J13="","",IFERROR(COUNTIFS('Weekly Log'!$H:$H,"Y",'Weekly Log'!$A:$A,">="&$J13,'Weekly Log'!$A:$A,"<"&$J13+7)/COUNTIFS('Weekly Log'!$H:$H,"<>",'Weekly Log'!$A:$A,">="&$J13,'Weekly Log'!$A:$A,"<"&$J13+7),0)) | E13: =IF($J13="","",IFERROR(AVERAGEIFS('Weekly Log'!$F:$F,'Weekly Log'!$A:$A,">="&$J13,'Weekly Log'!$A:$A,"<"&$J13+7),0)) | F13: =IF($J13="","",IFERROR(SUMIFS('Weekly Log'!$F:$F,'Weekly Log'!$A:$A,">="&$J13,'Weekly Log'!$A:$A,"<"&$J13+7)/SUMIFS('Weekly Log'!$E:$E,'Weekly Log'!$A:$A,">="&$J13,'Weekly Log'!$A:$A,"<"&$J13+7),0)) | G13: =IF($J13="","",IFERROR(LOOKUP(2,1/(('Weekly Log'!$A$5:$A$5000>=$J13)*('Weekly Log'!$A$5:$A$5000<$J13+7)*('Weekly Log'!$M$5:$M$5000<>"")),'Weekly Log'!$M$5:$M$5000),0)) | H13: Short week | J13: =IF(COUNT('Weekly Log'!$A$5:$A$5000)=0,"",IF(MIN('Weekly Log'!$A$5:$A$5000)+7*(ROW()-10)>MAX('Weekly Log'!$A$5:$A$5000),"",MIN('Weekly Log'!$A$5:$A$5000)+7*(ROW()-10)))
A14: =IF($J14="","",YEAR($J14-WEEKDAY($J14,2)+4)&"-W"&TEXT(WEEKNUM($J14,21),"00")) | B14: =IF($J14="","",SUMIFS('Weekly Log'!$C:$C,'Weekly Log'!$A:$A,">="&$J14,'Weekly Log'!$A:$A,"<"&$J14+7)) | C14: =IF($J14="","",IFERROR(COUNTIFS('Weekly Log'!$G:$G,"Y",'Weekly Log'!$A:$A,">="&$J14,'Weekly Log'!$A:$A,"<"&$J14+7)/COUNTIFS('Weekly Log'!$G:$G,"<>",'Weekly Log'!$A:$A,">="&$J14,'Weekly Log'!$A:$A,"<"&$J14+7),0)) | D14: =IF($J14="","",IFERROR(COUNTIFS('Weekly Log'!$H:$H,"Y",'Weekly Log'!$A:$A,">="&$J14,'Weekly Log'!$A:$A,"<"&$J14+7)/COUNTIFS('Weekly Log'!$H:$H,"<>",'Weekly Log'!$A:$A,">="&$J14,'Weekly Log'!$A:$A,"<"&$J14+7),0)) | E14: =IF($J14="","",IFERROR(AVERAGEIFS('Weekly Log'!$F:$F,'Weekly Log'!$A:$A,">="&$J14,'Weekly Log'!$A:$A,"<"&$J14+7),0)) | F14: =IF($J14="","",IFERROR(SUMIFS('Weekly Log'!$F:$F,'Weekly Log'!$A:$A,">="&$J14,'Weekly Log'!$A:$A,"<"&$J14+7)/SUMIFS('Weekly Log'!$E:$E,'Weekly Log'!$A:$A,">="&$J14,'Weekly Log'!$A:$A,"<"&$J14+7),0)) | G14: =IF($J14="","",IFERROR(LOOKUP(2,1/(('Weekly Log'!$A$5:$A$5000>=$J14)*('Weekly Log'!$A$5:$A$5000<$J14+7)*('Weekly Log'!$M$5:$M$5000<>"")),'Weekly Log'!$M$5:$M$5000),0)) | H14: Christmas week | J14: =IF(COUNT('Weekly Log'!$A$5:$A$5000)=0,"",IF(MIN('Weekly Log'!$A$5:$A$5000)+7*(ROW()-10)>MAX('Weekly Log'!$A$5:$A$5000),"",MIN('Weekly Log'!$A$5:$A$5000)+7*(ROW()-10)))
A15: =IF($J15="","",YEAR($J15-WEEKDAY($J15,2)+4)&"-W"&TEXT(WEEKNUM($J15,21),"00")) | B15: =IF($J15="","",SUMIFS('Weekly Log'!$C:$C,'Weekly Log'!$A:$A,">="&$J15,'Weekly Log'!$A:$A,"<"&$J15+7)) | C15: =IF($J15="","",IFERROR(COUNTIFS('Weekly Log'!$G:$G,"Y",'Weekly Log'!$A:$A,">="&$J15,'Weekly Log'!$A:$A,"<"&$J15+7)/COUNTIFS('Weekly Log'!$G:$G,"<>",'Weekly Log'!$A:$A,">="&$J15,'Weekly Log'!$A:$A,"<"&$J15+7),0)) | D15: =IF($J15="","",IFERROR(COUNTIFS('Weekly Log'!$H:$H,"Y",'Weekly Log'!$A:$A,">="&$J15,'Weekly Log'!$A:$A,"<"&$J15+7)/COUNTIFS('Weekly Log'!$H:$H,"<>",'Weekly Log'!$A:$A,">="&$J15,'Weekly Log'!$A:$A,"<"&$J15+7),0)) | E15: =IF($J15="","",IFERROR(AVERAGEIFS('Weekly Log'!$F:$F,'Weekly Log'!$A:$A,">="&$J15,'Weekly Log'!$A:$A,"<"&$J15+7),0)) | F15: =IF($J15="","",IFERROR(SUMIFS('Weekly Log'!$F:$F,'Weekly Log'!$A:$A,">="&$J15,'Weekly Log'!$A:$A,"<"&$J15+7)/SUMIFS('Weekly Log'!$E:$E,'Weekly Log'!$A:$A,">="&$J15,'Weekly Log'!$A:$A,"<"&$J15+7),0)) | G15: =IF($J15="","",IFERROR(LOOKUP(2,1/(('Weekly Log'!$A$5:$A$5000>=$J15)*('Weekly Log'!$A$5:$A$5000<$J15+7)*('Weekly Log'!$M$5:$M$5000<>"")),'Weekly Log'!$M$5:$M$5000),0)) | H15: New Years | J15: =IF(COUNT('Weekly Log'!$A$5:$A$5000)=0,"",IF(MIN('Weekly Log'!$A$5:$A$5000)+7*(ROW()-10)>MAX('Weekly Log'!$A$5:$A$5000),"",MIN('Weekly Log'!$A$5:$A$5000)+7*(ROW()-10)))
A16: =IF($J16="","",YEAR($J16-WEEKDAY($J16,2)+4)&"-W"&TEXT(WEEKNUM($J16,21),"00")) | B16: =IF($J16="","",SUMIFS('Weekly Log'!$C:$C,'Weekly Log'!$A:$A,">="&$J16,'Weekly Log'!$A:$A,"<"&$J16+7)) | C16: =IF($J16="","",IFERROR(COUNTIFS('Weekly Log'!$G:$G,"Y",'Weekly Log'!$A:$A,">="&$J16,'Weekly Log'!$A:$A,"<"&$J16+7)/COUNTIFS('Weekly Log'!$G:$G,"<>",'Weekly Log'!$A:$A,">="&$J16,'Weekly Log'!$A:$A,"<"&$J16+7),0)) | D16: =IF($J16="","",IFERROR(COUNTIFS('Weekly Log'!$H:$H,"Y",'Weekly Log'!$A:$A,">="&$J16,'Weekly Log'!$A:$A,"<"&$J16+7)/COUNTIFS('Weekly Log'!$H:$H,"<>",'Weekly Log'!$A:$A,">="&$J16,'Weekly Log'!$A:$A,"<"&$J16+7),0)) | E16: =IF($J16="","",IFERROR(AVERAGEIFS('Weekly Log'!$F:$F,'Weekly Log'!$A:$A,">="&$J16,'Weekly Log'!$A:$A,"<"&$J16+7),0)) | F16: =IF($J16="","",IFERROR(SUMIFS('Weekly Log'!$F:$F,'Weekly Log'!$A:$A,">="&$J16,'Weekly Log'!$A:$A,"<"&$J16+7)/SUMIFS('Weekly Log'!$E:$E,'Weekly Log'!$A:$A,">="&$J16,'Weekly Log'!$A:$A,"<"&$J16+7),0)) | G16: =IF($J16="","",IFERROR(LOOKUP(2,1/(('Weekly Log'!$A$5:$A$5000>=$J16)*('Weekly Log'!$A$5:$A$5000<$J16+7)*('Weekly Log'!$M$5:$M$5000<>"")),'Weekly Log'!$M$5:$M$5000),0)) | H16: Back to full staff | J16: =IF(COUNT('Weekly Log'!$A$5:$A$5000)=0,"",IF(MIN('Weekly Log'!$A$5:$A$5000)+7*(ROW()-10)>MAX('Weekly Log'!$A$5:$A$5000),"",MIN('Weekly Log'!$A$5:$A$5000)+7*(ROW()-10)))
A17: =IF($J17="","",YEAR($J17-WEEKDAY($J17,2)+4)&"-W"&TEXT(WEEKNUM($J17,21),"00")) | B17: =IF($J17="","",SUMIFS('Weekly Log'!$C:$C,'Weekly Log'!$A:$A,">="&$J17,'Weekly Log'!$A:$A,"<"&$J17+7)) | C17: =IF($J17="","",IFERROR(COUNTIFS('Weekly Log'!$G:$G,"Y",'Weekly Log'!$A:$A,">="&$J17,'Weekly Log'!$A:$A,"<"&$J17+7)/COUNTIFS('Weekly Log'!$G:$G,"<>",'Weekly Log'!$A:$A,">="&$J17,'Weekly Log'!$A:$A,"<"&$J17+7),0)) | D17: =IF($J17="","",IFERROR(COUNTIFS('Weekly Log'!$H:$H,"Y",'Weekly Log'!$A:$A,">="&$J17,'Weekly Log'!$A:$A,"<"&$J17+7)/COUNTIFS('Weekly Log'!$H:$H,"<>",'Weekly Log'!$A:$A,">="&$J17,'Weekly Log'!$A:$A,"<"&$J17+7),0)) | E17: =IF($J17="","",IFERROR(AVERAGEIFS('Weekly Log'!$F:$F,'Weekly Log'!$A:$A,">="&$J17,'Weekly Log'!$A:$A,"<"&$J17+7),0)) | F17: =IF($J17="","",IFERROR(SUMIFS('Weekly Log'!$F:$F,'Weekly Log'!$A:$A,">="&$J17,'Weekly Log'!$A:$A,"<"&$J17+7)/SUMIFS('Weekly Log'!$E:$E,'Weekly Log'!$A:$A,">="&$J17,'Weekly Log'!$A:$A,"<"&$J17+7),0)) | G17: =IF($J17="","",IFERROR(LOOKUP(2,1/(('Weekly Log'!$A$5:$A$5000>=$J17)*('Weekly Log'!$A$5:$A$5000<$J17+7)*('Weekly Log'!$M$5:$M$5000<>"")),'Weekly Log'!$M$5:$M$5000),0)) | J17: =IF(COUNT('Weekly Log'!$A$5:$A$5000)=0,"",IF(MIN('Weekly Log'!$A$5:$A$5000)+7*(ROW()-10)>MAX('Weekly Log'!$A$5:$A$5000),"",MIN('Weekly Log'!$A$5:$A$5000)+7*(ROW()-10)))
A18: =IF($J18="","",YEAR($J18-WEEKDAY($J18,2)+4)&"-W"&TEXT(WEEKNUM($J18,21),"00")) | B18: =IF($J18="","",SUMIFS('Weekly Log'!$C:$C,'Weekly Log'!$A:$A,">="&$J18,'Weekly Log'!$A:$A,"<"&$J18+7)) | C18: =IF($J18="","",IFERROR(COUNTIFS('Weekly Log'!$G:$G,"Y",'Weekly Log'!$A:$A,">="&$J18,'Weekly Log'!$A:$A,"<"&$J18+7)/COUNTIFS('Weekly Log'!$G:$G,"<>",'Weekly Log'!$A:$A,">="&$J18,'Weekly Log'!$A:$A,"<"&$J18+7),0)) | D18: =IF($J18="","",IFERROR(COUNTIFS('Weekly Log'!$H:$H,"Y",'Weekly Log'!$A:$A,">="&$J18,'Weekly Log'!$A:$A,"<"&$J18+7)/COUNTIFS('Weekly Log'!$H:$H,"<>",'Weekly Log'!$A:$A,">="&$J18,'Weekly Log'!$A:$A,"<"&$J18+7),0)) | E18: =IF($J18="","",IFERROR(AVERAGEIFS('Weekly Log'!$F:$F,'Weekly Log'!$A:$A,">="&$J18,'Weekly Log'!$A:$A,"<"&$J18+7),0)) | F18: =IF($J18="","",IFERROR(SUMIFS('Weekly Log'!$F:$F,'Weekly Log'!$A:$A,">="&$J18,'Weekly Log'!$A:$A,"<"&$J18+7)/SUMIFS('Weekly Log'!$E:$E,'Weekly Log'!$A:$A,">="&$J18,'Weekly Log'!$A:$A,"<"&$J18+7),0)) | G18: =IF($J18="","",IFERROR(LOOKUP(2,1/(('Weekly Log'!$A$5:$A$5000>=$J18)*('Weekly Log'!$A$5:$A$5000<$J18+7)*('Weekly Log'!$M$5:$M$5000<>"")),'Weekly Log'!$M$5:$M$5000),0)) | J18: =IF(COUNT('Weekly Log'!$A$5:$A$5000)=0,"",IF(MIN('Weekly Log'!$A$5:$A$5000)+7*(ROW()-10)>MAX('Weekly Log'!$A$5:$A$5000),"",MIN('Weekly Log'!$A$5:$A$5000)+7*(ROW()-10)))
A19: =IF($J19="","",YEAR($J19-WEEKDAY($J19,2)+4)&"-W"&TEXT(WEEKNUM($J19,21),"00")) | B19: =IF($J19="","",SUMIFS('Weekly Log'!$C:$C,'Weekly Log'!$A:$A,">="&$J19,'Weekly Log'!$A:$A,"<"&$J19+7)) | C19: =IF($J19="","",IFERROR(COUNTIFS('Weekly Log'!$G:$G,"Y",'Weekly Log'!$A:$A,">="&$J19,'Weekly Log'!$A:$A,"<"&$J19+7)/COUNTIFS('Weekly Log'!$G:$G,"<>",'Weekly Log'!$A:$A,">="&$J19,'Weekly Log'!$A:$A,"<"&$J19+7),0)) | D19: =IF($J19="","",IFERROR(COUNTIFS('Weekly Log'!$H:$H,"Y",'Weekly Log'!$A:$A,">="&$J19,'Weekly Log'!$A:$A,"<"&$J19+7)/COUNTIFS('Weekly Log'!$H:$H,"<>",'Weekly Log'!$A:$A,">="&$J19,'Weekly Log'!$A:$A,"<"&$J19+7),0)) | E19: =IF($J19="","",IFERROR(AVERAGEIFS('Weekly Log'!$F:$F,'Weekly Log'!$A:$A,">="&$J19,'Weekly Log'!$A:$A,"<"&$J19+7),0)) | F19: =IF($J19="","",IFERROR(SUMIFS('Weekly Log'!$F:$F,'Weekly Log'!$A:$A,">="&$J19,'Weekly Log'!$A:$A,"<"&$J19+7)/SUMIFS('Weekly Log'!$E:$E,'Weekly Log'!$A:$A,">="&$J19,'Weekly Log'!$A:$A,"<"&$J19+7),0)) | G19: =IF($J19="","",IFERROR(LOOKUP(2,1/(('Weekly Log'!$A$5:$A$5000>=$J19)*('Weekly Log'!$A$5:$A$5000<$J19+7)*('Weekly Log'!$M$5:$M$5000<>"")),'Weekly Log'!$M$5:$M$5000),0)) | J19: =IF(COUNT('Weekly Log'!$A$5:$A$5000)=0,"",IF(MIN('Weekly Log'!$A$5:$A$5000)+7*(ROW()-10)>MAX('Weekly Log'!$A$5:$A$5000),"",MIN('Weekly Log'!$A$5:$A$5000)+7*(ROW()-10)))
A20: =IF($J20="","",YEAR($J20-WEEKDAY($J20,2)+4)&"-W"&TEXT(WEEKNUM($J20,21),"00")) | B20: =IF($J20="","",SUMIFS('Weekly Log'!$C:$C,'Weekly Log'!$A:$A,">="&$J20,'Weekly Log'!$A:$A,"<"&$J20+7)) | C20: =IF($J20="","",IFERROR(COUNTIFS('Weekly Log'!$G:$G,"Y",'Weekly Log'!$A:$A,">="&$J20,'Weekly Log'!$A:$A,"<"&$J20+7)/COUNTIFS('Weekly Log'!$G:$G,"<>",'Weekly Log'!$A:$A,">="&$J20,'Weekly Log'!$A:$A,"<"&$J20+7),0)) | D20: =IF($J20="","",IFERROR(COUNTIFS('Weekly Log'!$H:$H,"Y",'Weekly Log'!$A:$A,">="&$J20,'Weekly Log'!$A:$A,"<"&$J20+7)/COUNTIFS('Weekly Log'!$H:$H,"<>",'Weekly Log'!$A:$A,">="&$J20,'Weekly Log'!$A:$A,"<"&$J20+7),0)) | E20: =IF($J20="","",IFERROR(AVERAGEIFS('Weekly Log'!$F:$F,'Weekly Log'!$A:$A,">="&$J20,'Weekly Log'!$A:$A,"<"&$J20+7),0)) | F20: =IF($J20="","",IFERROR(SUMIFS('Weekly Log'!$F:$F,'Weekly Log'!$A:$A,">="&$J20,'Weekly Log'!$A:$A,"<"&$J20+7)/SUMIFS('Weekly Log'!$E:$E,'Weekly Log'!$A:$A,">="&$J20,'Weekly Log'!$A:$A,"<"&$J20+7),0)) | G20: =IF($J20="","",IFERROR(LOOKUP(2,1/(('Weekly Log'!$A$5:$A$5000>=$J20)*('Weekly Log'!$A$5:$A$5000<$J20+7)*('Weekly Log'!$M$5:$M$5000<>"")),'Weekly Log'!$M$5:$M$5000),0)) | J20: =IF(COUNT('Weekly Log'!$A$5:$A$5000)=0,"",IF(MIN('Weekly Log'!$A$5:$A$5000)+7*(ROW()-10)>MAX('Weekly Log'!$A$5:$A$5000),"",MIN('Weekly Log'!$A$5:$A$5000)+7*(ROW()-10)))
A21: =IF($J21="","",YEAR($J21-WEEKDAY($J21,2)+4)&"-W"&TEXT(WEEKNUM($J21,21),"00")) | B21: =IF($J21="","",SUMIFS('Weekly Log'!$C:$C,'Weekly Log'!$A:$A,">="&$J21,'Weekly Log'!$A:$A,"<"&$J21+7)) | C21: =IF($J21="","",IFERROR(COUNTIFS('Weekly Log'!$G:$G,"Y",'Weekly Log'!$A:$A,">="&$J21,'Weekly Log'!$A:$A,"<"&$J21+7)/COUNTIFS('Weekly Log'!$G:$G,"<>",'Weekly Log'!$A:$A,">="&$J21,'Weekly Log'!$A:$A,"<"&$J21+7),0)) | D21: =IF($J21="","",IFERROR(COUNTIFS('Weekly Log'!$H:$H,"Y",'Weekly Log'!$A:$A,">="&$J21,'Weekly Log'!$A:$A,"<"&$J21+7)/COUNTIFS('Weekly Log'!$H:$H,"<>",'Weekly Log'!$A:$A,">="&$J21,'Weekly Log'!$A:$A,"<"&$J21+7),0)) | E21: =IF($J21="","",IFERROR(AVERAGEIFS('Weekly Log'!$F:$F,'Weekly Log'!$A:$A,">="&$J21,'Weekly Log'!$A:$A,"<"&$J21+7),0)) | F21: =IF($J21="","",IFERROR(SUMIFS('Weekly Log'!$F:$F,'Weekly Log'!$A:$A,">="&$J21,'Weekly Log'!$A:$A,"<"&$J21+7)/SUMIFS('Weekly Log'!$E:$E,'Weekly Log'!$A:$A,">="&$J21,'Weekly Log'!$A:$A,"<"&$J21+7),0)) | G21: =IF($J21="","",IFERROR(LOOKUP(2,1/(('Weekly Log'!$A$5:$A$5000>=$J21)*('Weekly Log'!$A$5:$A$5000<$J21+7)*('Weekly Log'!$M$5:$M$5000<>"")),'Weekly Log'!$M$5:$M$5000),0)) | J21: =IF(COUNT('Weekly Log'!$A$5:$A$5000)=0,"",IF(MIN('Weekly Log'!$A$5:$A$5000)+7*(ROW()-10)>MAX('Weekly Log'!$A$5:$A$5000),"",MIN('Weekly Log'!$A$5:$A$5000)+7*(ROW()-10)))
A22: =IF($J22="","",YEAR($J22-WEEKDAY($J22,2)+4)&"-W"&TEXT(WEEKNUM($J22,21),"00")) | B22: =IF($J22="","",SUMIFS('Weekly Log'!$C:$C,'Weekly Log'!$A:$A,">="&$J22,'Weekly Log'!$A:$A,"<"&$J22+7)) | C22: =IF($J22="","",IFERROR(COUNTIFS('Weekly Log'!$G:$G,"Y",'Weekly Log'!$A:$A,">="&$J22,'Weekly Log'!$A:$A,"<"&$J22+7)/COUNTIFS('Weekly Log'!$G:$G,"<>",'Weekly Log'!$A:$A,">="&$J22,'Weekly Log'!$A:$A,"<"&$J22+7),0)) | D22: =IF($J22="","",IFERROR(COUNTIFS('Weekly Log'!$H:$H,"Y",'Weekly Log'!$A:$A,">="&$J22,'Weekly Log'!$A:$A,"<"&$J22+7)/COUNTIFS('Weekly Log'!$H:$H,"<>",'Weekly Log'!$A:$A,">="&$J22,'Weekly Log'!$A:$A,"<"&$J22+7),0)) | E22: =IF($J22="","",IFERROR(AVERAGEIFS('Weekly Log'!$F:$F,'Weekly Log'!$A:$A,">="&$J22,'Weekly Log'!$A:$A,"<"&$J22+7),0)) | F22: =IF($J22="","",IFERROR(SUMIFS('Weekly Log'!$F:$F,'Weekly Log'!$A:$A,">="&$J22,'Weekly Log'!$A:$A,"<"&$J22+7)/SUMIFS('Weekly Log'!$E:$E,'Weekly Log'!$A:$A,">="&$J22,'Weekly Log'!$A:$A,"<"&$J22+7),0)) | G22: =IF($J22="","",IFERROR(LOOKUP(2,1/(('Weekly Log'!$A$5:$A$5000>=$J22)*('Weekly Log'!$A$5:$A$5000<$J22+7)*('Weekly Log'!$M$5:$M$5000<>"")),'Weekly Log'!$M$5:$M$5000),0)) | J22: =IF(COUNT('Weekly Log'!$A$5:$A$5000)=0,"",IF(MIN('Weekly Log'!$A$5:$A$5000)+7*(ROW()-10)>MAX('Weekly Log'!$A$5:$A$5000),"",MIN('Weekly Log'!$A$5:$A$5000)+7*(ROW()-10)))
A23: =IF($J23="","",YEAR($J23-WEEKDAY($J23,2)+4)&"-W"&TEXT(WEEKNUM($J23,21),"00")) | B23: =IF($J23="","",SUMIFS('Weekly Log'!$C:$C,'Weekly Log'!$A:$A,">="&$J23,'Weekly Log'!$A:$A,"<"&$J23+7)) | C23: =IF($J23="","",IFERROR(COUNTIFS('Weekly Log'!$G:$G,"Y",'Weekly Log'!$A:$A,">="&$J23,'Weekly Log'!$A:$A,"<"&$J23+7)/COUNTIFS('Weekly Log'!$G:$G,"<>",'Weekly Log'!$A:$A,">="&$J23,'Weekly Log'!$A:$A,"<"&$J23+7),0)) | D23: =IF($J23="","",IFERROR(COUNTIFS('Weekly Log'!$H:$H,"Y",'Weekly Log'!$A:$A,">="&$J23,'Weekly Log'!$A:$A,"<"&$J23+7)/COUNTIFS('Weekly Log'!$H:$H,"<>",'Weekly Log'!$A:$A,">="&$J23,'Weekly Log'!$A:$A,"<"&$J23+7),0)) | E23: =IF($J23="","",IFERROR(AVERAGEIFS('Weekly Log'!$F:$F,'Weekly Log'!$A:$A,">="&$J23,'Weekly Log'!$A:$A,"<"&$J23+7),0)) | F23: =IF($J23="","",IFERROR(SUMIFS('Weekly Log'!$F:$F,'Weekly Log'!$A:$A,">="&$J23,'Weekly Log'!$A:$A,"<"&$J23+7)/SUMIFS('Weekly Log'!$E:$E,'Weekly Log'!$A:$A,">="&$J23,'Weekly Log'!$A:$A,"<"&$J23+7),0)) | G23: =IF($J23="","",IFERROR(LOOKUP(2,1/(('Weekly Log'!$A$5:$A$5000>=$J23)*('Weekly Log'!$A$5:$A$5000<$J23+7)*('Weekly Log'!$M$5:$M$5000<>"")),'Weekly Log'!$M$5:$M$5000),0)) | J23: =IF(COUNT('Weekly Log'!$A$5:$A$5000)=0,"",IF(MIN('Weekly Log'!$A$5:$A$5000)+7*(ROW()-10)>MAX('Weekly Log'!$A$5:$A$5000),"",MIN('Weekly Log'!$A$5:$A$5000)+7*(ROW()-10)))
A24: =IF($J24="","",YEAR($J24-WEEKDAY($J24,2)+4)&"-W"&TEXT(WEEKNUM($J24,21),"00")) | B24: =IF($J24="","",SUMIFS('Weekly Log'!$C:$C,'Weekly Log'!$A:$A,">="&$J24,'Weekly Log'!$A:$A,"<"&$J24+7)) | C24: =IF($J24="","",IFERROR(COUNTIFS('Weekly Log'!$G:$G,"Y",'Weekly Log'!$A:$A,">="&$J24,'Weekly Log'!$A:$A,"<"&$J24+7)/COUNTIFS('Weekly Log'!$G:$G,"<>",'Weekly Log'!$A:$A,">="&$J24,'Weekly Log'!$A:$A,"<"&$J24+7),0)) | D24: =IF($J24="","",IFERROR(COUNTIFS('Weekly Log'!$H:$H,"Y",'Weekly Log'!$A:$A,">="&$J24,'Weekly Log'!$A:$A,"<"&$J24+7)/COUNTIFS('Weekly Log'!$H:$H,"<>",'Weekly Log'!$A:$A,">="&$J24,'Weekly Log'!$A:$A,"<"&$J24+7),0)) | E24: =IF($J24="","",IFERROR(AVERAGEIFS('Weekly Log'!$F:$F,'Weekly Log'!$A:$A,">="&$J24,'Weekly Log'!$A:$A,"<"&$J24+7),0)) | F24: =IF($J24="","",IFERROR(SUMIFS('Weekly Log'!$F:$F,'Weekly Log'!$A:$A,">="&$J24,'Weekly Log'!$A:$A,"<"&$J24+7)/SUMIFS('Weekly Log'!$E:$E,'Weekly Log'!$A:$A,">="&$J24,'Weekly Log'!$A:$A,"<"&$J24+7),0)) | G24: =IF($J24="","",IFERROR(LOOKUP(2,1/(('Weekly Log'!$A$5:$A$5000>=$J24)*('Weekly Log'!$A$5:$A$5000<$J24+7)*('Weekly Log'!$M$5:$M$5000<>"")),'Weekly Log'!$M$5:$M$5000),0)) | H24: Short week | J24: =IF(COUNT('Weekly Log'!$A$5:$A$5000)=0,"",IF(MIN('Weekly Log'!$A$5:$A$5000)+7*(ROW()-10)>MAX('Weekly Log'!$A$5:$A$5000),"",MIN('Weekly Log'!$A$5:$A$5000)+7*(ROW()-10)))
A25: =IF($J25="","",YEAR($J25-WEEKDAY($J25,2)+4)&"-W"&TEXT(WEEKNUM($J25,21),"00")) | B25: =IF($J25="","",SUMIFS('Weekly Log'!$C:$C,'Weekly Log'!$A:$A,">="&$J25,'Weekly Log'!$A:$A,"<"&$J25+7)) | C25: =IF($J25="","",IFERROR(COUNTIFS('Weekly Log'!$G:$G,"Y",'Weekly Log'!$A:$A,">="&$J25,'Weekly Log'!$A:$A,"<"&$J25+7)/COUNTIFS('Weekly Log'!$G:$G,"<>",'Weekly Log'!$A:$A,">="&$J25,'Weekly Log'!$A:$A,"<"&$J25+7),0)) | D25: =IF($J25="","",IFERROR(COUNTIFS('Weekly Log'!$H:$H,"Y",'Weekly Log'!$A:$A,">="&$J25,'Weekly Log'!$A:$A,"<"&$J25+7)/COUNTIFS('Weekly Log'!$H:$H,"<>",'Weekly Log'!$A:$A,">="&$J25,'Weekly Log'!$A:$A,"<"&$J25+7),0)) | E25: =IF($J25="","",IFERROR(AVERAGEIFS('Weekly Log'!$F:$F,'Weekly Log'!$A:$A,">="&$J25,'Weekly Log'!$A:$A,"<"&$J25+7),0)) | F25: =IF($J25="","",IFERROR(SUMIFS('Weekly Log'!$F:$F,'Weekly Log'!$A:$A,">="&$J25,'Weekly Log'!$A:$A,"<"&$J25+7)/SUMIFS('Weekly Log'!$E:$E,'Weekly Log'!$A:$A,">="&$J25,'Weekly Log'!$A:$A,"<"&$J25+7),0)) | G25: =IF($J25="","",IFERROR(LOOKUP(2,1/(('Weekly Log'!$A$5:$A$5000>=$J25)*('Weekly Log'!$A$5:$A$5000<$J25+7)*('Weekly Log'!$M$5:$M$5000<>"")),'Weekly Log'!$M$5:$M$5000),0)) | J25: =IF(COUNT('Weekly Log'!$A$5:$A$5000)=0,"",IF(MIN('Weekly Log'!$A$5:$A$5000)+7*(ROW()-10)>MAX('Weekly Log'!$A$5:$A$5000),"",MIN('Weekly Log'!$A$5:$A$5000)+7*(ROW()-10)))
A26: =IF($J26="","",YEAR($J26-WEEKDAY($J26,2)+4)&"-W"&TEXT(WEEKNUM($J26,21),"00")) | B26: =IF($J26="","",SUMIFS('Weekly Log'!$C:$C,'Weekly Log'!$A:$A,">="&$J26,'Weekly Log'!$A:$A,"<"&$J26+7)) | C26: =IF($J26="","",IFERROR(COUNTIFS('Weekly Log'!$G:$G,"Y",'Weekly Log'!$A:$A,">="&$J26,'Weekly Log'!$A:$A,"<"&$J26+7)/COUNTIFS('Weekly Log'!$G:$G,"<>",'Weekly Log'!$A:$A,">="&$J26,'Weekly Log'!$A:$A,"<"&$J26+7),0)) | D26: =IF($J26="","",IFERROR(COUNTIFS('Weekly Log'!$H:$H,"Y",'Weekly Log'!$A:$A,">="&$J26,'Weekly Log'!$A:$A,"<"&$J26+7)/COUNTIFS('Weekly Log'!$H:$H,"<>",'Weekly Log'!$A:$A,">="&$J26,'Weekly Log'!$A:$A,"<"&$J26+7),0)) | E26: =IF($J26="","",IFERROR(AVERAGEIFS('Weekly Log'!$F:$F,'Weekly Log'!$A:$A,">="&$J26,'Weekly Log'!$A:$A,"<"&$J26+7),0)) | F26: =IF($J26="","",IFERROR(SUMIFS('Weekly Log'!$F:$F,'Weekly Log'!$A:$A,">="&$J26,'Weekly Log'!$A:$A,"<"&$J26+7)/SUMIFS('Weekly Log'!$E:$E,'Weekly Log'!$A:$A,">="&$J26,'Weekly Log'!$A:$A,"<"&$J26+7),0)) | G26: =IF($J26="","",IFERROR(LOOKUP(2,1/(('Weekly Log'!$A$5:$A$5000>=$J26)*('Weekly Log'!$A$5:$A$5000<$J26+7)*('Weekly Log'!$M$5:$M$5000<>"")),'Weekly Log'!$M$5:$M$5000),0)) | H26: Weather delays | J26: =IF(COUNT('Weekly Log'!$A$5:$A$5000)=0,"",IF(MIN('Weekly Log'!$A$5:$A$5000)+7*(ROW()-10)>MAX('Weekly Log'!$A$5:$A$5000),"",MIN('Weekly Log'!$A$5:$A$5000)+7*(ROW()-10)))
A27: =IF($J27="","",YEAR($J27-WEEKDAY($J27,2)+4)&"-W"&TEXT(WEEKNUM($J27,21),"00")) | B27: =IF($J27="","",SUMIFS('Weekly Log'!$C:$C,'Weekly Log'!$A:$A,">="&$J27,'Weekly Log'!$A:$A,"<"&$J27+7)) | C27: =IF($J27="","",IFERROR(COUNTIFS('Weekly Log'!$G:$G,"Y",'Weekly Log'!$A:$A,">="&$J27,'Weekly Log'!$A:$A,"<"&$J27+7)/COUNTIFS('Weekly Log'!$G:$G,"<>",'Weekly Log'!$A:$A,">="&$J27,'Weekly Log'!$A:$A,"<"&$J27+7),0)) | D27: =IF($J27="","",IFERROR(COUNTIFS('Weekly Log'!$H:$H,"Y",'Weekly Log'!$A:$A,">="&$J27,'Weekly Log'!$A:$A,"<"&$J27+7)/COUNTIFS('Weekly Log'!$H:$H,"<>",'Weekly Log'!$A:$A,">="&$J27,'Weekly Log'!$A:$A,"<"&$J27+7),0)) | E27: =IF($J27="","",IFERROR(AVERAGEIFS('Weekly Log'!$F:$F,'Weekly Log'!$A:$A,">="&$J27,'Weekly Log'!$A:$A,"<"&$J27+7),0)) | F27: =IF($J27="","",IFERROR(SUMIFS('Weekly Log'!$F:$F,'Weekly Log'!$A:$A,">="&$J27,'Weekly Log'!$A:$A,"<"&$J27+7)/SUMIFS('Weekly Log'!$E:$E,'Weekly Log'!$A:$A,">="&$J27,'Weekly Log'!$A:$A,"<"&$J27+7),0)) | G27: =IF($J27="","",IFERROR(LOOKUP(2,1/(('Weekly Log'!$A$5:$A$5000>=$J27)*('Weekly Log'!$A$5:$A$5000<$J27+7)*('Weekly Log'!$M$5:$M$5000<>"")),'Weekly Log'!$M$5:$M$5000),0)) | J27: =IF(COUNT('Weekly Log'!$A$5:$A$5000)=0,"",IF(MIN('Weekly Log'!$A$5:$A$5000)+7*(ROW()-10)>MAX('Weekly Log'!$A$5:$A$5000),"",MIN('Weekly Log'!$A$5:$A$5000)+7*(ROW()-10)))
A28: =IF($J28="","",YEAR($J28-WEEKDAY($J28,2)+4)&"-W"&TEXT(WEEKNUM($J28,21),"00")) | B28: =IF($J28="","",SUMIFS('Weekly Log'!$C:$C,'Weekly Log'!$A:$A,">="&$J28,'Weekly Log'!$A:$A,"<"&$J28+7)) | C28: =IF($J28="","",IFERROR(COUNTIFS('Weekly Log'!$G:$G,"Y",'Weekly Log'!$A:$A,">="&$J28,'Weekly Log'!$A:$A,"<"&$J28+7)/COUNTIFS('Weekly Log'!$G:$G,"<>",'Weekly Log'!$A:$A,">="&$J28,'Weekly Log'!$A:$A,"<"&$J28+7),0)) | D28: =IF($J28="","",IFERROR(COUNTIFS('Weekly Log'!$H:$H,"Y",'Weekly Log'!$A:$A,">="&$J28,'Weekly Log'!$A:$A,"<"&$J28+7)/COUNTIFS('Weekly Log'!$H:$H,"<>",'Weekly Log'!$A:$A,">="&$J28,'Weekly Log'!$A:$A,"<"&$J28+7),0)) | E28: =IF($J28="","",IFERROR(AVERAGEIFS('Weekly Log'!$F:$F,'Weekly Log'!$A:$A,">="&$J28,'Weekly Log'!$A:$A,"<"&$J28+7),0)) | F28: =IF($J28="","",IFERROR(SUMIFS('Weekly Log'!$F:$F,'Weekly Log'!$A:$A,">="&$J28,'Weekly Log'!$A:$A,"<"&$J28+7)/SUMIFS('Weekly Log'!$E:$E,'Weekly Log'!$A:$A,">="&$J28,'Weekly Log'!$A:$A,"<"&$J28+7),0)) | G28: =IF($J28="","",IFERROR(LOOKUP(2,1/(('Weekly Log'!$A$5:$A$5000>=$J28)*('Weekly Log'!$A$5:$A$5000<$J28+7)*('Weekly Log'!$M$5:$M$5000<>"")),'Weekly Log'!$M$5:$M$5000),0)) | J28: =IF(COUNT('Weekly Log'!$A$5:$A$5000)=0,"",IF(MIN('Weekly Log'!$A$5:$A$5000)+7*(ROW()-10)>MAX('Weekly Log'!$A$5:$A$5000),"",MIN('Weekly Log'!$A$5:$A$5000)+7*(ROW()-10)))
A29: =IF($J29="","",YEAR($J29-WEEKDAY($J29,2)+4)&"-W"&TEXT(WEEKNUM($J29,21),"00")) | B29: =IF($J29="","",SUMIFS('Weekly Log'!$C:$C,'Weekly Log'!$A:$A,">="&$J29,'Weekly Log'!$A:$A,"<"&$J29+7)) | C29: =IF($J29="","",IFERROR(COUNTIFS('Weekly Log'!$G:$G,"Y",'Weekly Log'!$A:$A,">="&$J29,'Weekly Log'!$A:$A,"<"&$J29+7)/COUNTIFS('Weekly Log'!$G:$G,"<>",'Weekly Log'!$A:$A,">="&$J29,'Weekly Log'!$A:$A,"<"&$J29+7),0)) | D29: =IF($J29="","",IFERROR(COUNTIFS('Weekly Log'!$H:$H,"Y",'Weekly Log'!$A:$A,">="&$J29,'Weekly Log'!$A:$A,"<"&$J29+7)/COUNTIFS('Weekly Log'!$H:$H,"<>",'Weekly Log'!$A:$A,">="&$J29,'Weekly Log'!$A:$A,"<"&$J29+7),0)) | E29: =IF($J29="","",IFERROR(AVERAGEIFS('Weekly Log'!$F:$F,'Weekly Log'!$A:$A,">="&$J29,'Weekly Log'!$A:$A,"<"&$J29+7),0)) | F29: =IF($J29="","",IFERROR(SUMIFS('Weekly Log'!$F:$F,'Weekly Log'!$A:$A,">="&$J29,'Weekly Log'!$A:$A,"<"&$J29+7)/SUMIFS('Weekly Log'!$E:$E,'Weekly Log'!$A:$A,">="&$J29,'Weekly Log'!$A:$A,"<"&$J29+7),0)) | G29: =IF($J29="","",IFERROR(LOOKUP(2,1/(('Weekly Log'!$A$5:$A$5000>=$J29)*('Weekly Log'!$A$5:$A$5000<$J29+7)*('Weekly Log'!$M$5:$M$5000<>"")),'Weekly Log'!$M$5:$M$5000),0)) | J29: =IF(COUNT('Weekly Log'!$A$5:$A$5000)=0,"",IF(MIN('Weekly Log'!$A$5:$A$5000)+7*(ROW()-10)>MAX('Weekly Log'!$A$5:$A$5000),"",MIN('Weekly Log'!$A$5:$A$5000)+7*(ROW()-10)))
A30: =IF($J30="","",YEAR($J30-WEEKDAY($J30,2)+4)&"-W"&TEXT(WEEKNUM($J30,21),"00")) | B30: =IF($J30="","",SUMIFS('Weekly Log'!$C:$C,'Weekly Log'!$A:$A,">="&$J30,'Weekly Log'!$A:$A,"<"&$J30+7)) | C30: =IF($J30="","",IFERROR(COUNTIFS('Weekly Log'!$G:$G,"Y",'Weekly Log'!$A:$A,">="&$J30,'Weekly Log'!$A:$A,"<"&$J30+7)/COUNTIFS('Weekly Log'!$G:$G,"<>",'Weekly Log'!$A:$A,">="&$J30,'Weekly Log'!$A:$A,"<"&$J30+7),0)) | D30: =IF($J30="","",IFERROR(COUNTIFS('Weekly Log'!$H:$H,"Y",'Weekly Log'!$A:$A,">="&$J30,'Weekly Log'!$A:$A,"<"&$J30+7)/COUNTIFS('Weekly Log'!$H:$H,"<>",'Weekly Log'!$A:$A,">="&$J30,'Weekly Log'!$A:$A,"<"&$J30+7),0)) | E30: =IF($J30="","",IFERROR(AVERAGEIFS('Weekly Log'!$F:$F,'Weekly Log'!$A:$A,">="&$J30,'Weekly Log'!$A:$A,"<"&$J30+7),0)) | F30: =IF($J30="","",IFERROR(SUMIFS('Weekly Log'!$F:$F,'Weekly Log'!$A:$A,">="&$J30,'Weekly Log'!$A:$A,"<"&$J30+7)/SUMIFS('Weekly Log'!$E:$E,'Weekly Log'!$A:$A,">="&$J30,'Weekly Log'!$A:$A,"<"&$J30+7),0)) | G30: =IF($J30="","",IFERROR(LOOKUP(2,1/(('Weekly Log'!$A$5:$A$5000>=$J30)*('Weekly Log'!$A$5:$A$5000<$J30+7)*('Weekly Log'!$M$5:$M$5000<>"")),'Weekly Log'!$M$5:$M$5000),0)) | J30: =IF(COUNT('Weekly Log'!$A$5:$A$5000)=0,"",IF(MIN('Weekly Log'!$A$5:$A$5000)+7*(ROW()-10)>MAX('Weekly Log'!$A$5:$A$5000),"",MIN('Weekly Log'!$A$5:$A$5000)+7*(ROW()-10)))
A31: =IF($J31="","",YEAR($J31-WEEKDAY($J31,2)+4)&"-W"&TEXT(WEEKNUM($J31,21),"00")) | B31: =IF($J31="","",SUMIFS('Weekly Log'!$C:$C,'Weekly Log'!$A:$A,">="&$J31,'Weekly Log'!$A:$A,"<"&$J31+7)) | C31: =IF($J31="","",IFERROR(COUNTIFS('Weekly Log'!$G:$G,"Y",'Weekly Log'!$A:$A,">="&$J31,'Weekly Log'!$A:$A,"<"&$J31+7)/COUNTIFS('Weekly Log'!$G:$G,"<>",'Weekly Log'!$A:$A,">="&$J31,'Weekly Log'!$A:$A,"<"&$J31+7),0)) | D31: =IF($J31="","",IFERROR(COUNTIFS('Weekly Log'!$H:$H,"Y",'Weekly Log'!$A:$A,">="&$J31,'Weekly Log'!$A:$A,"<"&$J31+7)/COUNTIFS('Weekly Log'!$H:$H,"<>",'Weekly Log'!$A:$A,">="&$J31,'Weekly Log'!$A:$A,"<"&$J31+7),0)) | E31: =IF($J31="","",IFERROR(AVERAGEIFS('Weekly Log'!$F:$F,'Weekly Log'!$A:$A,">="&$J31,'Weekly Log'!$A:$A,"<"&$J31+7),0)) | F31: =IF($J31="","",IFERROR(SUMIFS('Weekly Log'!$F:$F,'Weekly Log'!$A:$A,">="&$J31,'Weekly Log'!$A:$A,"<"&$J31+7)/SUMIFS('Weekly Log'!$E:$E,'Weekly Log'!$A:$A,">="&$J31,'Weekly Log'!$A:$A,"<"&$J31+7),0)) | G31: =IF($J31="","",IFERROR(LOOKUP(2,1/(('Weekly Log'!$A$5:$A$5000>=$J31)*('Weekly Log'!$A$5:$A$5000<$J31+7)*('Weekly Log'!$M$5:$M$5000<>"")),'Weekly Log'!$M$5:$M$5000),0)) | J31: =IF(COUNT('Weekly Log'!$A$5:$A$5000)=0,"",IF(MIN('Weekly Log'!$A$5:$A$5000)+7*(ROW()-10)>MAX('Weekly Log'!$A$5:$A$5000),"",MIN('Weekly Log'!$A$5:$A$5000)+7*(ROW()-10)))
A32: =IF($J32="","",YEAR($J32-WEEKDAY($J32,2)+4)&"-W"&TEXT(WEEKNUM($J32,21),"00")) | B32: =IF($J32="","",SUMIFS('Weekly Log'!$C:$C,'Weekly Log'!$A:$A,">="&$J32,'Weekly Log'!$A:$A,"<"&$J32+7)) | C32: =IF($J32="","",IFERROR(COUNTIFS('Weekly Log'!$G:$G,"Y",'Weekly Log'!$A:$A,">="&$J32,'Weekly Log'!$A:$A,"<"&$J32+7)/COUNTIFS('Weekly Log'!$G:$G,"<>",'Weekly Log'!$A:$A,">="&$J32,'Weekly Log'!$A:$A,"<"&$J32+7),0)) | D32: =IF($J32="","",IFERROR(COUNTIFS('Weekly Log'!$H:$H,"Y",'Weekly Log'!$A:$A,">="&$J32,'Weekly Log'!$A:$A,"<"&$J32+7)/COUNTIFS('Weekly Log'!$H:$H,"<>",'Weekly Log'!$A:$A,">="&$J32,'Weekly Log'!$A:$A,"<"&$J32+7),0)) | E32: =IF($J32="","",IFERROR(AVERAGEIFS('Weekly Log'!$F:$F,'Weekly Log'!$A:$A,">="&$J32,'Weekly Log'!$A:$A,"<"&$J32+7),0)) | F32: =IF($J32="","",IFERROR(SUMIFS('Weekly Log'!$F:$F,'Weekly Log'!$A:$A,">="&$J32,'Weekly Log'!$A:$A,"<"&$J32+7)/SUMIFS('Weekly Log'!$E:$E,'Weekly Log'!$A:$A,">="&$J32,'Weekly Log'!$A:$A,"<"&$J32+7),0)) | G32: =IF($J32="","",IFERROR(LOOKUP(2,1/(('Weekly Log'!$A$5:$A$5000>=$J32)*('Weekly Log'!$A$5:$A$5000<$J32+7)*('Weekly Log'!$M$5:$M$5000<>"")),'Weekly Log'!$M$5:$M$5000),0)) | J32: =IF(COUNT('Weekly Log'!$A$5:$A$5000)=0,"",IF(MIN('Weekly Log'!$A$5:$A$5000)+7*(ROW()-10)>MAX('Weekly Log'!$A$5:$A$5000),"",MIN('Weekly Log'!$A$5:$A$5000)+7*(ROW()-10)))
A33: =IF($J33="","",YEAR($J33-WEEKDAY($J33,2)+4)&"-W"&TEXT(WEEKNUM($J33,21),"00")) | B33: =IF($J33="","",SUMIFS('Weekly Log'!$C:$C,'Weekly Log'!$A:$A,">="&$J33,'Weekly Log'!$A:$A,"<"&$J33+7)) | C33: =IF($J33="","",IFERROR(COUNTIFS('Weekly Log'!$G:$G,"Y",'Weekly Log'!$A:$A,">="&$J33,'Weekly Log'!$A:$A,"<"&$J33+7)/COUNTIFS('Weekly Log'!$G:$G,"<>",'Weekly Log'!$A:$A,">="&$J33,'Weekly Log'!$A:$A,"<"&$J33+7),0)) | D33: =IF($J33="","",IFERROR(COUNTIFS('Weekly Log'!$H:$H,"Y",'Weekly Log'!$A:$A,">="&$J33,'Weekly Log'!$A:$A,"<"&$J33+7)/COUNTIFS('Weekly Log'!$H:$H,"<>",'Weekly Log'!$A:$A,">="&$J33,'Weekly Log'!$A:$A,"<"&$J33+7),0)) | E33: =IF($J33="","",IFERROR(AVERAGEIFS('Weekly Log'!$F:$F,'Weekly Log'!$A:$A,">="&$J33,'Weekly Log'!$A:$A,"<"&$J33+7),0)) | F33: =IF($J33="","",IFERROR(SUMIFS('Weekly Log'!$F:$F,'Weekly Log'!$A:$A,">="&$J33,'Weekly Log'!$A:$A,"<"&$J33+7)/SUMIFS('Weekly Log'!$E:$E,'Weekly Log'!$A:$A,">="&$J33,'Weekly Log'!$A:$A,"<"&$J33+7),0)) | G33: =IF($J33="","",IFERROR(LOOKUP(2,1/(('Weekly Log'!$A$5:$A$5000>=$J33)*('Weekly Log'!$A$5:$A$5000<$J33+7)*('Weekly Log'!$M$5:$M$5000<>"")),'Weekly Log'!$M$5:$M$5000),0)) | J33: =IF(COUNT('Weekly Log'!$A$5:$A$5000)=0,"",IF(MIN('Weekly Log'!$A$5:$A$5000)+7*(ROW()-10)>MAX('Weekly Log'!$A$5:$A$5000),"",MIN('Weekly Log'!$A$5:$A$5000)+7*(ROW()-10)))
A34: =IF($J34="","",YEAR($J34-WEEKDAY($J34,2)+4)&"-W"&TEXT(WEEKNUM($J34,21),"00")) | B34: =IF($J34="","",SUMIFS('Weekly Log'!$C:$C,'Weekly Log'!$A:$A,">="&$J34,'Weekly Log'!$A:$A,"<"&$J34+7)) | C34: =IF($J34="","",IFERROR(COUNTIFS('Weekly Log'!$G:$G,"Y",'Weekly Log'!$A:$A,">="&$J34,'Weekly Log'!$A:$A,"<"&$J34+7)/COUNTIFS('Weekly Log'!$G:$G,"<>",'Weekly Log'!$A:$A,">="&$J34,'Weekly Log'!$A:$A,"<"&$J34+7),0)) | D34: =IF($J34="","",IFERROR(COUNTIFS('Weekly Log'!$H:$H,"Y",'Weekly Log'!$A:$A,">="&$J34,'Weekly Log'!$A:$A,"<"&$J34+7)/COUNTIFS('Weekly Log'!$H:$H,"<>",'Weekly Log'!$A:$A,">="&$J34,'Weekly Log'!$A:$A,"<"&$J34+7),0)) | E34: =IF($J34="","",IFERROR(AVERAGEIFS('Weekly Log'!$F:$F,'Weekly Log'!$A:$A,">="&$J34,'Weekly Log'!$A:$A,"<"&$J34+7),0)) | F34: =IF($J34="","",IFERROR(SUMIFS('Weekly Log'!$F:$F,'Weekly Log'!$A:$A,">="&$J34,'Weekly Log'!$A:$A,"<"&$J34+7)/SUMIFS('Weekly Log'!$E:$E,'Weekly Log'!$A:$A,">="&$J34,'Weekly Log'!$A:$A,"<"&$J34+7),0)) | G34: =IF($J34="","",IFERROR(LOOKUP(2,1/(('Weekly Log'!$A$5:$A$5000>=$J34)*('Weekly Log'!$A$5:$A$5000<$J34+7)*('Weekly Log'!$M$5:$M$5000<>"")),'Weekly Log'!$M$5:$M$5000),0)) | H34: Seasonal demand spike | J34: =IF(COUNT('Weekly Log'!$A$5:$A$5000)=0,"",IF(MIN('Weekly Log'!$A$5:$A$5000)+7*(ROW()-10)>MAX('Weekly Log'!$A$5:$A$5000),"",MIN('Weekly Log'!$A$5:$A$5000)+7*(ROW()-10)))
A35: =IF($J35="","",YEAR($J35-WEEKDAY($J35,2)+4)&"-W"&TEXT(WEEKNUM($J35,21),"00")) | B35: =IF($J35="","",SUMIFS('Weekly Log'!$C:$C,'Weekly Log'!$A:$A,">="&$J35,'Weekly Log'!$A:$A,"<"&$J35+7)) | C35: =IF($J35="","",IFERROR(COUNTIFS('Weekly Log'!$G:$G,"Y",'Weekly Log'!$A:$A,">="&$J35,'Weekly Log'!$A:$A,"<"&$J35+7)/COUNTIFS('Weekly Log'!$G:$G,"<>",'Weekly Log'!$A:$A,">="&$J35,'Weekly Log'!$A:$A,"<"&$J35+7),0)) | D35: =IF($J35="","",IFERROR(COUNTIFS('Weekly Log'!$H:$H,"Y",'Weekly Log'!$A:$A,">="&$J35,'Weekly Log'!$A:$A,"<"&$J35+7)/COUNTIFS('Weekly Log'!$H:$H,"<>",'Weekly Log'!$A:$A,">="&$J35,'Weekly Log'!$A:$A,"<"&$J35+7),0)) | E35: =IF($J35="","",IFERROR(AVERAGEIFS('Weekly Log'!$F:$F,'Weekly Log'!$A:$A,">="&$J35,'Weekly Log'!$A:$A,"<"&$J35+7),0)) | F35: =IF($J35="","",IFERROR(SUMIFS('Weekly Log'!$F:$F,'Weekly Log'!$A:$A,">="&$J35,'Weekly Log'!$A:$A,"<"&$J35+7)/SUMIFS('Weekly Log'!$E:$E,'Weekly Log'!$A:$A,">="&$J35,'Weekly Log'!$A:$A,"<"&$J35+7),0)) | G35: =IF($J35="","",IFERROR(LOOKUP(2,1/(('Weekly Log'!$A$5:$A$5000>=$J35)*('Weekly Log'!$A$5:$A$5000<$J35+7)*('Weekly Log'!$M$5:$M$5000<>"")),'Weekly Log'!$M$5:$M$5000),0)) | J35: =IF(COUNT('Weekly Log'!$A$5:$A$5000)=0,"",IF(MIN('Weekly Log'!$A$5:$A$5000)+7*(ROW()-10)>MAX('Weekly Log'!$A$5:$A$5000),"",MIN('Weekly Log'!$A$5:$A$5000)+7*(ROW()-10)))
A36: =IF($J36="","",YEAR($J36-WEEKDAY($J36,2)+4)&"-W"&TEXT(WEEKNUM($J36,21),"00")) | B36: =IF($J36="","",SUMIFS('Weekly Log'!$C:$C,'Weekly Log'!$A:$A,">="&$J36,'Weekly Log'!$A:$A,"<"&$J36+7)) | C36: =IF($J36="","",IFERROR(COUNTIFS('Weekly Log'!$G:$G,"Y",'Weekly Log'!$A:$A,">="&$J36,'Weekly Log'!$A:$A,"<"&$J36+7)/COUNTIFS('Weekly Log'!$G:$G,"<>",'Weekly Log'!$A:$A,">="&$J36,'Weekly Log'!$A:$A,"<"&$J36+7),0)) | D36: =IF($J36="","",IFERROR(COUNTIFS('Weekly Log'!$H:$H,"Y",'Weekly Log'!$A:$A,">="&$J36,'Weekly Log'!$A:$A,"<"&$J36+7)/COUNTIFS('Weekly Log'!$H:$H,"<>",'Weekly Log'!$A:$A,">="&$J36,'Weekly Log'!$A:$A,"<"&$J36+7),0)) | E36: =IF($J36="","",IFERROR(AVERAGEIFS('Weekly Log'!$F:$F,'Weekly Log'!$A:$A,">="&$J36,'Weekly Log'!$A:$A,"<"&$J36+7),0)) | F36: =IF($J36="","",IFERROR(SUMIFS('Weekly Log'!$F:$F,'Weekly Log'!$A:$A,">="&$J36,'Weekly Log'!$A:$A,"<"&$J36+7)/SUMIFS('Weekly Log'!$E:$E,'Weekly Log'!$A:$A,">="&$J36,'Weekly Log'!$A:$A,"<"&$J36+7),0)) | G36: =IF($J36="","",IFERROR(LOOKUP(2,1/(('Weekly Log'!$A$5:$A$5000>=$J36)*('Weekly Log'!$A$5:$A$5000<$J36+7)*('Weekly Log'!$M$5:$M$5000<>"")),'Weekly Log'!$M$5:$M$5000),0)) | J36: =IF(COUNT('Weekly Log'!$A$5:$A$5000)=0,"",IF(MIN('Weekly Log'!$A$5:$A$5000)+7*(ROW()-10)>MAX('Weekly Log'!$A$5:$A$5000),"",MIN('Weekly Log'!$A$5:$A$5000)+7*(ROW()-10)))
A37: =IF($J37="","",YEAR($J37-WEEKDAY($J37,2)+4)&"-W"&TEXT(WEEKNUM($J37,21),"00")) | B37: =IF($J37="","",SUMIFS('Weekly Log'!$C:$C,'Weekly Log'!$A:$A,">="&$J37,'Weekly Log'!$A:$A,"<"&$J37+7)) | C37: =IF($J37="","",IFERROR(COUNTIFS('Weekly Log'!$G:$G,"Y",'Weekly Log'!$A:$A,">="&$J37,'Weekly Log'!$A:$A,"<"&$J37+7)/COUNTIFS('Weekly Log'!$G:$G,"<>",'Weekly Log'!$A:$A,">="&$J37,'Weekly Log'!$A:$A,"<"&$J37+7),0)) | D37: =IF($J37="","",IFERROR(COUNTIFS('Weekly Log'!$H:$H,"Y",'Weekly Log'!$A:$A,">="&$J37,'Weekly Log'!$A:$A,"<"&$J37+7)/COUNTIFS('Weekly Log'!$H:$H,"<>",'Weekly Log'!$A:$A,">="&$J37,'Weekly Log'!$A:$A,"<"&$J37+7),0)) | E37: =IF($J37="","",IFERROR(AVERAGEIFS('Weekly Log'!$F:$F,'Weekly Log'!$A:$A,">="&$J37,'Weekly Log'!$A:$A,"<"&$J37+7),0)) | F37: =IF($J37="","",IFERROR(SUMIFS('Weekly Log'!$F:$F,'Weekly Log'!$A:$A,">="&$J37,'Weekly Log'!$A:$A,"<"&$J37+7)/SUMIFS('Weekly Log'!$E:$E,'Weekly Log'!$A:$A,">="&$J37,'Weekly Log'!$A:$A,"<"&$J37+7),0)) | G37: =IF($J37="","",IFERROR(LOOKUP(2,1/(('Weekly Log'!$A$5:$A$5000>=$J37)*('Weekly Log'!$A$5:$A$5000<$J37+7)*('Weekly Log'!$M$5:$M$5000<>"")),'Weekly Log'!$M$5:$M$5000),0)) | H37: Short week | J37: =IF(COUNT('Weekly Log'!$A$5:$A$5000)=0,"",IF(MIN('Weekly Log'!$A$5:$A$5000)+7*(ROW()-10)>MAX('Weekly Log'!$A$5:$A$5000),"",MIN('Weekly Log'!$A$5:$A$5000)+7*(ROW()-10)))
A38: =IF($J38="","",YEAR($J38-WEEKDAY($J38,2)+4)&"-W"&TEXT(WEEKNUM($J38,21),"00")) | B38: =IF($J38="","",SUMIFS('Weekly Log'!$C:$C,'Weekly Log'!$A:$A,">="&$J38,'Weekly Log'!$A:$A,"<"&$J38+7)) | C38: =IF($J38="","",IFERROR(COUNTIFS('Weekly Log'!$G:$G,"Y",'Weekly Log'!$A:$A,">="&$J38,'Weekly Log'!$A:$A,"<"&$J38+7)/COUNTIFS('Weekly Log'!$G:$G,"<>",'Weekly Log'!$A:$A,">="&$J38,'Weekly Log'!$A:$A,"<"&$J38+7),0)) | D38: =IF($J38="","",IFERROR(COUNTIFS('Weekly Log'!$H:$H,"Y",'Weekly Log'!$A:$A,">="&$J38,'Weekly Log'!$A:$A,"<"&$J38+7)/COUNTIFS('Weekly Log'!$H:$H,"<>",'Weekly Log'!$A:$A,">="&$J38,'Weekly Log'!$A:$A,"<"&$J38+7),0)) | E38: =IF($J38="","",IFERROR(AVERAGEIFS('Weekly Log'!$F:$F,'Weekly Log'!$A:$A,">="&$J38,'Weekly Log'!$A:$A,"<"&$J38+7),0)) | F38: =IF($J38="","",IFERROR(SUMIFS('Weekly Log'!$F:$F,'Weekly Log'!$A:$A,">="&$J38,'Weekly Log'!$A:$A,"<"&$J38+7)/SUMIFS('Weekly Log'!$E:$E,'Weekly Log'!$A:$A,">="&$J38,'Weekly Log'!$A:$A,"<"&$J38+7),0)) | G38: =IF($J38="","",IFERROR(LOOKUP(2,1/(('Weekly Log'!$A$5:$A$5000>=$J38)*('Weekly Log'!$A$5:$A$5000<$J38+7)*('Weekly Log'!$M$5:$M$5000<>"")),'Weekly Log'!$M$5:$M$5000),0)) | J38: =IF(COUNT('Weekly Log'!$A$5:$A$5000)=0,"",IF(MIN('Weekly Log'!$A$5:$A$5000)+7*(ROW()-10)>MAX('Weekly Log'!$A$5:$A$5000),"",MIN('Weekly Log'!$A$5:$A$5000)+7*(ROW()-10)))
A39: =IF($J39="","",YEAR($J39-WEEKDAY($J39,2)+4)&"-W"&TEXT(WEEKNUM($J39,21),"00")) | B39: =IF($J39="","",SUMIFS('Weekly Log'!$C:$C,'Weekly Log'!$A:$A,">="&$J39,'Weekly Log'!$A:$A,"<"&$J39+7)) | C39: =IF($J39="","",IFERROR(COUNTIFS('Weekly Log'!$G:$G,"Y",'Weekly Log'!$A:$A,">="&$J39,'Weekly Log'!$A:$A,"<"&$J39+7)/COUNTIFS('Weekly Log'!$G:$G,"<>",'Weekly Log'!$A:$A,">="&$J39,'Weekly Log'!$A:$A,"<"&$J39+7),0)) | D39: =IF($J39="","",IFERROR(COUNTIFS('Weekly Log'!$H:$H,"Y",'Weekly Log'!$A:$A,">="&$J39,'Weekly Log'!$A:$A,"<"&$J39+7)/COUNTIFS('Weekly Log'!$H:$H,"<>",'Weekly Log'!$A:$A,">="&$J39,'Weekly Log'!$A:$A,"<"&$J39+7),0)) | E39: =IF($J39="","",IFERROR(AVERAGEIFS('Weekly Log'!$F:$F,'Weekly Log'!$A:$A,">="&$J39,'Weekly Log'!$A:$A,"<"&$J39+7),0)) | F39: =IF($J39="","",IFERROR(SUMIFS('Weekly Log'!$F:$F,'Weekly Log'!$A:$A,">="&$J39,'Weekly Log'!$A:$A,"<"&$J39+7)/SUMIFS('Weekly Log'!$E:$E,'Weekly Log'!$A:$A,">="&$J39,'Weekly Log'!$A:$A,"<"&$J39+7),0)) | G39: =IF($J39="","",IFERROR(LOOKUP(2,1/(('Weekly Log'!$A$5:$A$5000>=$J39)*('Weekly Log'!$A$5:$A$5000<$J39+7)*('Weekly Log'!$M$5:$M$5000<>"")),'Weekly Log'!$M$5:$M$5000),0)) | J39: =IF(COUNT('Weekly Log'!$A$5:$A$5000)=0,"",IF(MIN('Weekly Log'!$A$5:$A$5000)+7*(ROW()-10)>MAX('Weekly Log'!$A$5:$A$5000),"",MIN('Weekly Log'!$A$5:$A$5000)+7*(ROW()-10)))
A40: =IF($J40="","",YEAR($J40-WEEKDAY($J40,2)+4)&"-W"&TEXT(WEEKNUM($J40,21),"00")) | B40: =IF($J40="","",SUMIFS('Weekly Log'!$C:$C,'Weekly Log'!$A:$A,">="&$J40,'Weekly Log'!$A:$A,"<"&$J40+7)) | C40: =IF($J40="","",IFERROR(COUNTIFS('Weekly Log'!$G:$G,"Y",'Weekly Log'!$A:$A,">="&$J40,'Weekly Log'!$A:$A,"<"&$J40+7)/COUNTIFS('Weekly Log'!$G:$G,"<>",'Weekly Log'!$A:$A,">="&$J40,'Weekly Log'!$A:$A,"<"&$J40+7),0)) | D40: =IF($J40="","",IFERROR(COUNTIFS('Weekly Log'!$H:$H,"Y",'Weekly Log'!$A:$A,">="&$J40,'Weekly Log'!$A:$A,"<"&$J40+7)/COUNTIFS('Weekly Log'!$H:$H,"<>",'Weekly Log'!$A:$A,">="&$J40,'Weekly Log'!$A:$A,"<"&$J40+7),0)) | E40: =IF($J40="","",IFERROR(AVERAGEIFS('Weekly Log'!$F:$F,'Weekly Log'!$A:$A,">="&$J40,'Weekly Log'!$A:$A,"<"&$J40+7),0)) | F40: =IF($J40="","",IFERROR(SUMIFS('Weekly Log'!$F:$F,'Weekly Log'!$A:$A,">="&$J40,'Weekly Log'!$A:$A,"<"&$J40+7)/SUMIFS('Weekly Log'!$E:$E,'Weekly Log'!$A:$A,">="&$J40,'Weekly Log'!$A:$A,"<"&$J40+7),0)) | G40: =IF($J40="","",IFERROR(LOOKUP(2,1/(('Weekly Log'!$A$5:$A$5000>=$J40)*('Weekly Log'!$A$5:$A$5000<$J40+7)*('Weekly Log'!$M$5:$M$5000<>"")),'Weekly Log'!$M$5:$M$5000),0)) | H40: Seasonal demand spike | J40: =IF(COUNT('Weekly Log'!$A$5:$A$5000)=0,"",IF(MIN('Weekly Log'!$A$5:$A$5000)+7*(ROW()-10)>MAX('Weekly Log'!$A$5:$A$5000),"",MIN('Weekly Log'!$A$5:$A$5000)+7*(ROW()-10)))
A41: =IF($J41="","",YEAR($J41-WEEKDAY($J41,2)+4)&"-W"&TEXT(WEEKNUM($J41,21),"00")) | B41: =IF($J41="","",SUMIFS('Weekly Log'!$C:$C,'Weekly Log'!$A:$A,">="&$J41,'Weekly Log'!$A:$A,"<"&$J41+7)) | C41: =IF($J41="","",IFERROR(COUNTIFS('Weekly Log'!$G:$G,"Y",'Weekly Log'!$A:$A,">="&$J41,'Weekly Log'!$A:$A,"<"&$J41+7)/COUNTIFS('Weekly Log'!$G:$G,"<>",'Weekly Log'!$A:$A,">="&$J41,'Weekly Log'!$A:$A,"<"&$J41+7),0)) | D41: =IF($J41="","",IFERROR(COUNTIFS('Weekly Log'!$H:$H,"Y",'Weekly Log'!$A:$A,">="&$J41,'Weekly Log'!$A:$A,"<"&$J41+7)/COUNTIFS('Weekly Log'!$H:$H,"<>",'Weekly Log'!$A:$A,">="&$J41,'Weekly Log'!$A:$A,"<"&$J41+7),0)) | E41: =IF($J41="","",IFERROR(AVERAGEIFS('Weekly Log'!$F:$F,'Weekly Log'!$A:$A,">="&$J41,'Weekly Log'!$A:$A,"<"&$J41+7),0)) | F41: =IF($J41="","",IFERROR(SUMIFS('Weekly Log'!$F:$F,'Weekly Log'!$A:$A,">="&$J41,'Weekly Log'!$A:$A,"<"&$J41+7)/SUMIFS('Weekly Log'!$E:$E,'Weekly Log'!$A:$A,">="&$J41,'Weekly Log'!$A:$A,"<"&$J41+7),0)) | G41: =IF($J41="","",IFERROR(LOOKUP(2,1/(('Weekly Log'!$A$5:$A$5000>=$J41)*('Weekly Log'!$A$5:$A$5000<$J41+7)*('Weekly Log'!$M$5:$M$5000<>"")),'Weekly Log'!$M$5:$M$5000),0)) | J41: =IF(COUNT('Weekly Log'!$A$5:$A$5000)=0,"",IF(MIN('Weekly Log'!$A$5:$A$5000)+7*(ROW()-10)>MAX('Weekly Log'!$A$5:$A$5000),"",MIN('Weekly Log'!$A$5:$A$5000)+7*(ROW()-10)))
A42: =IF($J42="","",YEAR($J42-WEEKDAY($J42,2)+4)&"-W"&TEXT(WEEKNUM($J42,21),"00")) | B42: =IF($J42="","",SUMIFS('Weekly Log'!$C:$C,'Weekly Log'!$A:$A,">="&$J42,'Weekly Log'!$A:$A,"<"&$J42+7)) | C42: =IF($J42="","",IFERROR(COUNTIFS('Weekly Log'!$G:$G,"Y",'Weekly Log'!$A:$A,">="&$J42,'Weekly Log'!$A:$A,"<"&$J42+7)/COUNTIFS('Weekly Log'!$G:$G,"<>",'Weekly Log'!$A:$A,">="&$J42,'Weekly Log'!$A:$A,"<"&$J42+7),0)) | D42: =IF($J42="","",IFERROR(COUNTIFS('Weekly Log'!$H:$H,"Y",'Weekly Log'!$A:$A,">="&$J42,'Weekly Log'!$A:$A,"<"&$J42+7)/COUNTIFS('Weekly Log'!$H:$H,"<>",'Weekly Log'!$A:$A,">="&$J42,'Weekly Log'!$A:$A,"<"&$J42+7),0)) | E42: =IF($J42="","",IFERROR(AVERAGEIFS('Weekly Log'!$F:$F,'Weekly Log'!$A:$A,">="&$J42,'Weekly Log'!$A:$A,"<"&$J42+7),0)) | F42: =IF($J42="","",IFERROR(SUMIFS('Weekly Log'!$F:$F,'Weekly Log'!$A:$A,">="&$J42,'Weekly Log'!$A:$A,"<"&$J42+7)/SUMIFS('Weekly Log'!$E:$E,'Weekly Log'!$A:$A,">="&$J42,'Weekly Log'!$A:$A,"<"&$J42+7),0)) | G42: =IF($J42="","",IFERROR(LOOKUP(2,1/(('Weekly Log'!$A$5:$A$5000>=$J42)*('Weekly Log'!$A$5:$A$5000<$J42+7)*('Weekly Log'!$M$5:$M$5000<>"")),'Weekly Log'!$M$5:$M$5000),0)) | J42: =IF(COUNT('Weekly Log'!$A$5:$A$5000)=0,"",IF(MIN('Weekly Log'!$A$5:$A$5000)+7*(ROW()-10)>MAX('Weekly Log'!$A$5:$A$5000),"",MIN('Weekly Log'!$A$5:$A$5000)+7*(ROW()-10)))
...

Sheet Weekly Log
A1: SignalStack | Ops Pulse — Weekly Job Log
A2: Enter one row per job. All Dashboard KPIs pull from this sheet.
A3: Date | B3: Job ID | C3: Jobs Completed | D3: Technician | E3: Scheduled Time (h) | F3: Actual Time (h) | G3: On Time? (Y/N) | H3: Callback? (Y/N) | I3: On-Time Rate | J3: Callback Rate | K3: Avg Duration | L3: Utilization % | M3: Open WOs
I4: AUTO-CALCULATED — DO NOT EDIT
A5: 45614 | B5: JOB-1001 | C5: 1 | D5: Tech D | E5: 3.4 | F5: 2.9 | G5: Y | H5: N | I5: =COUNTIF(G$5:G5,"Y")/COUNTA(G$5:G5) | J5: =COUNTIF(H$5:H5,"Y")/COUNTA(H$5:H5) | K5: =AVERAGE(F$5:F5) | L5: =SUM(F$5:F5)/SUM(E$5:E5)
A6: 45615 | B6: JOB-1002 | C6: 1 | D6: Tech A | E6: 2.4 | F6: 1.9 | G6: Y | H6: N | I6: =COUNTIF(G$5:G6,"Y")/COUNTA(G$5:G6) | J6: =COUNTIF(H$5:H6,"Y")/COUNTA(H$5:H6) | K6: =AVERAGE(F$5:F6) | L6: =SUM(F$5:F6)/SUM(E$5:E6)
A7: 45616 | B7: JOB-1003 | C7: 1 | D7: Tech A | E7: 4.5 | F7: 3.2 | G7: Y | H7: N | I7: =COUNTIF(G$5:G7,"Y")/COUNTA(G$5:G7) | J7: =COUNTIF(H$5:H7,"Y")/COUNTA(H$5:H7) | K7: =AVERAGE(F$5:F7) | L7: =SUM(F$5:F7)/SUM(E$5:E7)
A8: 45617 | B8: JOB-1004 | C8: 1 | D8: Tech C | E8: 4.4 | F8: 3.7 | G8: Y | H8: N | I8: =COUNTIF(G$5:G8,"Y")/COUNTA(G$5:G8) | J8: =COUNTIF(H$5:H8,"Y")/COUNTA(H$5:H8) | K8: =AVERAGE(F$5:F8) | L8: =SUM(F$5:F8)/SUM(E$5:E8)
A9: 45618 | B9: JOB-1005 | C9: 1 | D9: Tech G | E9: 2.7 | F9: 2.3 | G9: Y | H9: N | I9: =COUNTIF(G$5:G9,"Y")/COUNTA(G$5:G9) | J9: =COUNTIF(H$5:H9,"Y")/COUNTA(H$5:H9) | K9: =AVERAGE(F$5:F9) | L9: =SUM(F$5:F9)/SUM(E$5:E9)
A10: 45614 | B10: JOB-1006 | C10: 1 | D10: Tech G | E10: 2.3 | F10: 1.7 | G10: Y | H10: N | I10: =COUNTIF(G$5:G10,"Y")/COUNTA(G$5:G10) | J10: =COUNTIF(H$5:H10,"Y")/COUNTA(H$5:H10) | K10: =AVERAGE(F$5:F10) | L10: =SUM(F$5:F10)/SUM(E$5:E10)
A11: 45615 | B11: JOB-1007 | C11: 1 | D11: Tech C | E11: 1.5 | F11: 1.2 | G11: Y | H11: N | I11: =COUNTIF(G$5:G11,"Y")/COUNTA(G$5:G11) | J11: =COUNTIF(H$5:H11,"Y")/COUNTA(H$5:H11) | K11: =AVERAGE(F$5:F11) | L11: =SUM(F$5:F11)/SUM(E$5:E11)
A12: 45616 | B12: JOB-1008 | C12: 1 | D12: Tech B | E12: 4.1 | F12: 3 | G12: Y | H12: N | I12: =COUNTIF(G$5:G12,"Y")/COUNTA(G$5:G12) | J12: =COUNTIF(H$5:H12,"Y")/COUNTA(H$5:H12) | K12: =AVERAGE(F$5:F12) | L12: =SUM(F$5:F12)/SUM(E$5:E12)
A13: 45617 | B13: JOB-1009 | C13: 1 | D13: Tech A | E13: 2.4 | F13: 1.7 | G13: Y | H13: N | I13: =COUNTIF(G$5:G13,"Y")/COUNTA(G$5:G13) | J13: =COUNTIF(H$5:H13,"Y")/COUNTA(H$5:H13) | K13: =AVERAGE(F$5:F13) | L13: =SUM(F$5:F13)/SUM(E$5:E13)
A14: 45618 | B14: JOB-1010 | C14: 1 | D14: Tech B | E14: 3.9 | F14: 3.4 | G14: Y | H14: N | I14: =COUNTIF(G$5:G14,"Y")/COUNTA(G$5:G14) | J14: =COUNTIF(H$5:H14,"Y")/COUNTA(H$5:H14) | K14: =AVERAGE(F$5:F14) | L14: =SUM(F$5:F14)/SUM(E$5:E14)
A15: 45614 | B15: JOB-1011 | C15: 1 | D15: Tech F | E15: 4.9 | F15: 3.4 | G15: Y | H15: N | I15: =COUNTIF(G$5:G15,"Y")/COUNTA(G$5:G15) | J15: =COUNTIF(H$5:H15,"Y")/COUNTA(H$5:H15) | K15: =AVERAGE(F$5:F15) | L15: =SUM(F$5:F15)/SUM(E$5:E15)
A16: 45615 | B16: JOB-1012 | C16: 1 | D16: Tech A | E16: 2.5 | F16: 2.1 | G16: Y | H16: N | I16: =COUNTIF(G$5:G16,"Y")/COUNTA(G$5:G16) | J16: =COUNTIF(H$5:H16,"Y")/COUNTA(H$5:H16) | K16: =AVERAGE(F$5:F16) | L16: =SUM(F$5:F16)/SUM(E$5:E16)
... A39: 45618 | B39: JOB-1035 | C39: 1 | D39: Tech H | E39: 0.6 | F39: 0.5 | G39: Y | H39: N | I39: =COUNTIF(G$5:G39,"Y")/COUNTA(G$5:G39) | J39: =COUNTIF(H$5:H39,"Y")/COUNTA(H$5:H39) | K39: =AVERAGE(F$5:F39) | L39: =SUM(F$5:F39)/SUM(E$5:E39)
A40: 45614 | B40: JOB-1036 | C40: 1 | D40: Tech H | E40: 2.7 | F40: 0.5 | G40: Y | H40: N | I40: =COUNTIF(G$5:G40,"Y")/COUNTA(G$5:G40) | J40: =COUNTIF(H$5:H40,"Y")/COUNTA(H$5:H40) | K40: =AVERAGE(F$5:F40) | L40: =SUM(F$5:F40)/SUM(E$5:E40) | M40: 16
A41: 45621 | B41: JOB-1037 | C41: 1 | D41: Tech H | E41: 2 | F41: 1.6 | G41: Y | H41: N | I41: =COUNTIF(G$5:G41,"Y")/COUNTA(G$5:G41) | J41: =COUNTIF(H$5:H41,"Y")/COUNTA(H$5:H41) | K41: =AVERAGE(F$5:F41) | L41: =SUM(F$5:F41)/SUM(E$5:E41)
A42: 45622 | B42: JOB-1038 | C42: 1 | D42: Tech F | E42: 5.3 | F42: 3.8 | G42: Y | H42: N | I42: =COUNTIF(G$5:G42,"Y")/COUNTA(G$5:G42) | J42: =COUNTIF(H$5:H42,"Y")/COUNTA(H$5:H42) | K42: =AVERAGE(F$5:F42) | L42: =SUM(F$5:F42)/SUM(E$5:E42)
A43: 45623 | B43: JOB-1039 | C43: 1 | D43: Tech B | E43: 3 | F43: 2.2 | G43: Y | H43: N | I43: =COUNTIF(G$5:G43,"Y")/COUNTA(G$5:G43) | J43: =COUNTIF(H$5:H43,"Y")/COUNTA(H$5:H43) | K43: =AVERAGE(F$5:F43) | L43: =SUM(F$5:F43)/SUM(E$5:E43)
A44: 45624 | B44: JOB-1040 | C44: 1 | D44: Tech C | E44: 1.7 | F44: 1.4 | G44: Y | H44: N | I44: =COUNTIF(G$5:G44,"Y")/COUNTA(G$5:G44) | J44: =COUNTIF(H$5:H44,"Y")/COUNTA(H$5:H44) | K44: =AVERAGE(F$5:F44) | L44: =SUM(F$5:F44)/SUM(E$5:E44)
A45: 45625 | B45: JOB-1041 | C45: 1 | D45: Tech C | E45: 2.7 | F45: 2 | G45: Y | H45: Y | I45: =COUNTIF(G$5:G45,"Y")/COUNTA(G$5:G45) | J45: =COUNTIF(H$5:H45,"Y")/COUNTA(H$5:H45) | K45: =AVERAGE(F$5:F45) | L45: =SUM(F$5:F45)/SUM(E$5:E45)
A46: 45621 | B46: JOB-1042 | C46: 1 | D46: Tech F | E46: 2.1 | F46: 1.7 | G46: Y | H46: N | I46: =COUNTIF(G$5:G46,"Y")/COUNTA(G$5:G46) | J46: =COUNTIF(H$5:H46,"Y")/COUNTA(H$5:H46) | K46: =AVERAGE(F$5:F46) | L46: =SUM(F$5:F46)/SUM(E$5:E46)
A47: 45622 | B47: JOB-1043 | C47: 1 | D47: Tech B | E47: 1.7 | F47: 1.2 | G47: Y | H47: N | I47: =COUNTIF(G$5:G47,"Y")/COUNTA(G$5:G47) | J47: =COUNTIF(H$5:H47,"Y")/COUNTA(H$5:H47) | K47: =AVERAGE(F$5:F47) | L47: =SUM(F$5:F47)/SUM(E$5:E47)
A48: 45623 | B48: JOB-1044 | C48: 1 | D48: Tech H | E48: 2.5 | F48: 1.7 | G48: Y | H48: N | I48: =COUNTIF(G$5:G48,"Y")/COUNTA(G$5:G48) | J48: =COUNTIF(H$5:H48,"Y")/COUNTA(H$5:H48) | K48: =AVERAGE(F$5:F48) | L48: =SUM(F$5:F48)/SUM(E$5:E48)
A49: 45624 | B49: JOB-1045 | C49: 1 | D49: Tech C | E49: 4 | F49: 3.4 | G49: Y | H49: N | I49: =COUNTIF(G$5:G49,"Y")/COUNTA(G$5:G49) | J49: =COUNTIF(H$5:H49,"Y")/COUNTA(H$5:H49) | K49: =AVERAGE(F$5:F49) | L49: =SUM(F$5:F49)/SUM(E$5:E49)
A50: 45625 | B50: JOB-1046 | C50: 1 | D50: Tech B | E50: 2.4 | F50: 1.7 | G50: Y | H50: N | I50: =COUNTIF(G$5:G50,"Y")/COUNTA(G$5:G50) | J50: =COUNTIF(H$5:H50,"Y")/COUNTA(H$5:H50) | K50: =AVERAGE(F$5:F50) | L50: =SUM(F$5:F50)/SUM(E$5:E50)
A51: 45621 | B51: JOB-1047 | C51: 1 | D51: Tech H | E51: 1.9 | F51: 1.6 | G51: Y | H51: N | I51: =COUNTIF(G$5:G51,"Y")/COUNTA(G$5:G51) | J51: =COUNTIF(H$5:H51,"Y")/COUNTA(H$5:H51) | K51: =AVERAGE(F$5:F51) | L51: =SUM(F$5:F51)/SUM(E$5:E51)
A52: 45622 | B52: JOB-1048 | C52: 1 | D52: Tech H | E52: 4.9 | F52: 3.6 | G52: N | H52: N | I52: =COUNTIF(G$5:G52,"Y")/COUNTA(G$5:G52) | J52: =COUNTIF(H$5:H52,"Y")/COUNTA(H$5:H52) | K52: =AVERAGE(F$5:F52) | L52: =SUM(F$5:F52)/SUM(E$5:E52)
... A77: 45622 | B77: JOB-1073 | C77: 1 | D77: Tech D | E77: 0.7 | F77: 0.5 | G77: Y | H77: N | I77: =COUNTIF(G$5:G77,"Y")/COUNTA(G$5:G77) | J77: =COUNTIF(H$5:H77,"Y")/COUNTA(H$5:H77) | K77: =AVERAGE(F$5:F77) | L77: =SUM(F$5:F77)/SUM(E$5:E77)
A78: 45623 | B78: JOB-1074 | C78: 1 | D78: Tech F | E78: 1.5 | F78: 0.5 | G78: N | H78: N | I78: =COUNTIF(G$5:G78,"Y")/COUNTA(G$5:G78) | J78: =COUNTIF(H$5:H78,"Y")/COUNTA(H$5:H78) | K78: =AVERAGE(F$5:F78) | L78: =SUM(F$5:F78)/SUM(E$5:E78) | M78: 15
A79: 45628 | B79: JOB-1075 | C79: 1 | D79: Tech A | E79: 1.4 | F79: 1.2 | G79: Y | H79: N | I79: =COUNTIF(G$5:G79,"Y")/COUNTA(G$5:G79) | J79: =COUNTIF(H$5:H79,"Y")/COUNTA(H$5:H79) | K79: =AVERAGE(F$5:F79) | L79: =SUM(F$5:F79)/SUM(E$5:E79)
A80: 45629 | B80: JOB-1076 | C80: 1 | D80: Tech A | E80: 5.8 | F80: 3.8 | G80: Y | H80: N | I80: =COUNTIF(G$5:G80,"Y")/COUNTA(G$5:G80) | J80: =COUNTIF(H$5:H80,"Y")/COUNTA(H$5:H80) | K80: =AVERAGE(F$5:F80) | L80: =SUM(F$5:F80)/SUM(E$5:E80)
A81: 45630 | B81: JOB-1077 | C81: 1 | D81: Tech B | E81: 4.2 | F81: 2.8 | G81: Y | H81: N | I81: =COUNTIF(G$5:G81,"Y")/COUNTA(G$5:G81) | J81: =COUNTIF(H$5:H81,"Y")/COUNTA(H$5:H81) | K81: =AVERAGE(F$5:F81) | L81: =SUM(F$5:F81)/SUM(E$5:E81)
A82: 45631 | B82: JOB-1078 | C82: 1 | D82: Tech D | E82: 3.5 | F82: 2.9 | G82: Y | H82: N | I82: =COUNTIF(G$5:G82,"Y")/COUNTA(G$5:G82) | J82: =COUNTIF(H$5:H82,"Y")/COUNTA(H$5:H82) | K82: =AVERAGE(F$5:F82) | L82: =SUM(F$5:F82)/SUM(E$5:E82)
A83: 45632 | B83: JOB-1079 | C83: 1 | D83: Tech F | E83: 1.9 | F83: 1.5 | G83: N | H83: N | I83: =COUNTIF(G$5:G83,"Y")/COUNTA(G$5:G83) | J83: =COUNTIF(H$5:H83,"Y")/COUNTA(H$5:H83) | K83: =AVERAGE(F$5:F83) | L83: =SUM(F$5:F83)/SUM(E$5:E83)
A84: 45628 | B84: JOB-1080 | C84: 1 | D84: Tech G | E84: 5.6 | F84: 3.8 | G84: Y | H84: N | I84: =COUNTIF(G$5:G84,"Y")/COUNTA(G$5:G84) | J84: =COUNTIF(H$5:H84,"Y")/COUNTA(H$5:H84) | K84: =AVERAGE(F$5:F84) | L84: =SUM(F$5:F84)/SUM(E$5:E84)
A85: 45629 | B85: JOB-1081 | C85: 1 | D85: Tech G | E85: 5.6 | F85: 3.7 | G85: Y | H85: N | I85: =COUNTIF(G$5:G85,"Y")/COUNTA(G$5:G85) | J85: =COUNTIF(H$5:H85,"Y")/COUNTA(H$5:H85) | K85: =AVERAGE(F$5:F85) | L85: =SUM(F$5:F85)/SUM(E$5:E85)
A86: 45630 | B86: JOB-1082 | C86: 1 | D86: Tech A | E86: 2.3 | F86: 1.8 | G86: Y | H86: N | I86: =COUNTIF(G$5:G86,"Y")/COUNTA(G$5:G86) | J86: =COUNTIF(H$5:H86,"Y")/COUNTA(H$5:H86) | K86: =AVERAGE(F$5:F86) | L86: =SUM(F$5:F86)/SUM(E$5:E86)
...

Sheet Benchmarks
A1: SignalStack | Ops Pulse — Target Benchmarks
A2: Set your targets here. Red/yellow/green flags on Dashboard compare actuals against these.
A3: Metric | B3: Your Target | C3: Industry Avg | D3: Notes
A4: On-Time Rate | B4: 0.92 | C4: 0.85 | D4: Best-in-class field service = 95%+
A5: Callback Rate | B5: 0.04 | C5: 0.07 | D5: Under 3% = excellent; over 8% = investigate
A6: Avg Job Duration | B6: 2.5 | C6: 3.1 | D6: Track in hours. Benchmark varies by trade.
A7: Crew Utilization | B7: 0.8 | C7: 0.72 | D7: 80-85% is the sweet spot. Over 90% = burnout risk.
A8: Jobs per Tech/Wk | B8: 10 | C8: 8 | D8: Adjust based on job complexity
